Workbook

Sheet Sheet1
A1: Id | B1: Startzeit | C1: Fertigstellungszeit | D1: E-Mail | E1: Name | F1: Gruppenfarbe | G1: Gruppe Blau | H1: Gruppe Grün | I1: Gruppe | J1: Posten | K1: Ball Stafette | L1: Paarlauf | M1: Bottle-Flip | N1: Kaplaturm | O1: Tic-Tac-Toe | P1: Glocken-Frisbee | Q1: Papierflieger | R1: Wasser schöpfen | S1: Tennisball-Zielwurf
A2: 259 | B2: 45468.479 | C2: 45468.486 | D2: anonym | F2: Blau | G2: Giraffe blau | I2: =OfficeForms.Table[[#This Row],[Gruppe Blau]]&OfficeForms.Table[[#This Row],[Gruppe Grün]] -> Giraffe blau | J2: Bottle-Flip | M2: 1
A3: 195 | B3: 45468.442 | C3: 45468.45 | D3: anonym | F3: Grün | H3: Krebs grün | I3: =OfficeForms.Table[[#This Row],[Gruppe Blau]]&OfficeForms.Table[[#This Row],[Gruppe Grün]] -> Krebs grün | J3: Bottle-Flip | M3: 3
A4: 220 | B4: 45468.456 | C4: 45468.467 | D4: anonym | F4: Grün | H4: Eule grün | I4: =OfficeForms.Table[[#This Row],[Gruppe Blau]]&OfficeForms.Table[[#This Row],[Gruppe Grün]] -> Eule grün | J4: Bottle-Flip | M4: 4
A5: 232 | B5: 45468.467 | C5: 45468.473 | D5: anonym | F5: Grün | H5: Fuchs grün | I5: =OfficeForms.Table[[#This Row],[Gruppe Blau]]&OfficeForms.Table[[#This Row],[Gruppe Grün]] -> Fuchs grün | J5: Bottle-Flip | M5: 4
A6: 194 | B6: 45468.442 | C6: 45468.45 | D6: anonym | F6: Blau | G6: Krebs blau | I6: =OfficeForms.Table[[#This Row],[Gruppe Blau]]&OfficeForms.Table[[#This Row],[Gruppe Grün]] -> Krebs blau | J6: Bottle-Flip | M6: 4
A7: 121 | B7: 45468.398 | C7: 45468.405 | D7: anonym | F7: Blau | G7: Panda blau | I7: =OfficeForms.Table[[#This Row],[Gruppe Blau]]&OfficeForms.Table[[#This Row],[Gruppe Grün]] -> Panda blau | J7: Bottle-Flip | M7: 4
A8: 181 | B8: 45468.436 | C8: 45468.442 | D8: anonym | F8: Grün | H8: Affe grün | I8: =OfficeForms.Table[[#This Row],[Gruppe Blau]]&OfficeForms.Table[[#This Row],[Gruppe Grün]] -> Affe grün | J8: Bottle-Flip | M8: 5
A9: 166 | B9: 45468.411 | C9: 45468.436 | D9: anonym | F9: Grün | H9: Schaf grün | I9: =OfficeForms.Table[[#This Row],[Gruppe Blau]]&OfficeForms.Table[[#This Row],[Gruppe Grün]] -> Schaf grün | J9: Bottle-Flip | M9: 5
A10: 207 | B10: 45468.45 | C10: 45468.456 | D10: anonym | F10: Grün | H10: Schildkröte grün | I10: =OfficeForms.Table[[#This Row],[Gruppe Blau]]&OfficeForms.Table[[#This Row],[Gruppe Grün]] -> Schildkröte grün | J10: Bottle-Flip | M10: 5
A11: 36 | B11: 45468.34 | C11: 45468.36 | D11: anonym | F11: Grün | H11: Giraffe grün | I11: =OfficeForms.Table[[#This Row],[Gruppe Blau]]&OfficeForms.Table[[#This Row],[Gruppe Grün]] -> Giraffe grün | J11: Bottle-Flip | M11: 6
A12: 245 | B12: 45468.475 | C12: 45468.479 | D12: anonym | F12: Blau | G12: Igel blau | I12: =OfficeForms.Table[[#This Row],[Gruppe Blau]]&OfficeForms.Table[[#This Row],[Gruppe Grün]] -> Igel blau | J12: Bottle-Flip | M12: 6
A13: 89 | B13: 45468.377 | C13: 45468.382 | D13: anonym | F13: Grün | H13: Delfin grün | I13: =OfficeForms.Table[[#This Row],[Gruppe Blau]]&OfficeForms.Table[[#This Row],[Gruppe Grün]] -> Delfin grün | J13: Bottle-Flip | M13: 7
A14: 52 | B14: 45468.36 | C14: 45468.366 | D14: anonym | F14: Grün | H14: Elefant grün | I14: =OfficeForms.Table[[#This Row],[Gruppe Blau]]&OfficeForms.Table[[#This Row],[Gruppe Grün]] -> Elefant grün | J14: Bottle-Flip | M14: 7
A15: 114 | B15: 45468.392 | C15: 45468.398 | D15: anonym | F15: Grün | H15: Tiger grün | I15: =OfficeForms.Table[[#This Row],[Gruppe Blau]]&OfficeForms.Table[[#This Row],[Gruppe Grün]] -> Tiger grün | J15: Bottle-Flip | M15: 7
A16: 184 | B16: 45468.436 | C16: 45468.442 | D16: anonym | F16: Blau | G16: Affe blau | I16: =OfficeForms.Table[[#This Row],[Gruppe Blau]]&OfficeForms.Table[[#This Row],[Gruppe Grün]] -> Affe blau | J16: Bottle-Flip | M16: 8
A17: 69 | B17: 45468.372 | C17: 45468.377 | D17: anonym | F17: Blau | G17: Katze blau | I17: =OfficeForms.Table[[#This Row],[Gruppe Blau]]&OfficeForms.Table[[#This Row],[Gruppe Grün]] -> Katze blau | J17: Bottle-Flip | M17: 8
A18: 137 | B18: 45468.405 | C18: 45468.411 | D18: anonym | F18: Grün | H18: Nilpferd grün | I18: =OfficeForms.Table[[#This Row],[Gruppe Blau]]&OfficeForms.Table[[#This Row],[Gruppe Grün]] -> Nilpferd grün | J18: Bottle-Flip | M18: 8
A19: 64 | B19: 45468.366 | C19: 45468.372 | D19: anonym | F19: Blau | G19: Schlange blau | I19: =OfficeForms.Table[[#This Row],[Gruppe Blau]]&OfficeForms.Table[[#This Row],[Gruppe Grün]] -> Schlange blau | J19: Bottle-Flip | M19: 8
A20: 95 | B20: 45468.382 | C20: 45468.391 | D20: anonym | F20: Blau | G20: Schmetterling blau | I20: =OfficeForms.Table[[#This Row],[Gruppe Blau]]&OfficeForms.Table[[#This Row],[Gruppe Grün]] -> Schmetterling blau | J20: Bottle-Flip | M20: 8
A21: 135 | B21: 45468.405 | C21: 45468.411 | D21: anonym | F21: Blau | G21: Nilpferd blau | I21: =OfficeForms.Table[[#This Row],[Gruppe Blau]]&OfficeForms.Table[[#This Row],[Gruppe Grün]] -> Nilpferd blau | J21: Bottle-Flip | M21: 9
A22: 165 | B22: 45468.411 | C22: 45468.436 | D22: anonym | F22: Blau | G22: Schaf blau | I22: =OfficeForms.Table[[#This Row],[Gruppe Blau]]&OfficeForms.Table[[#This Row],[Gruppe Grün]] -> Schaf blau | J22: Bottle-Flip | M22: 9
A23: 206 | B23: 45468.45 | C23: 45468.455 | D23: anonym | F23: Blau | G23: Schildkröte blau | I23: =OfficeForms.Table[[#This Row],[Gruppe Blau]]&OfficeForms.Table[[#This Row],[Gruppe Grün]] -> Schildkröte blau | J23: Bottle-Flip | M23: 9
A24: 96 | B24: 45468.382 | C24: 45468.392 | D24: anonym | F24: Grün | H24: Schmetterling grün | I24: =OfficeForms.Table[[#This Row],[Gruppe Blau]]&OfficeForms.Table[[#This Row],[Gruppe Grün]] -> Schmetterling grün | J24: Bottle-Flip | M24: 9
A25: 113 | B25: 45468.391 | C25: 45468.398 | D25: anonym | F25: Blau | G25: Tiger blau | I25: =OfficeForms.Table[[#This Row],[Gruppe Blau]]&OfficeForms.Table[[#This Row],[Gruppe Grün]] -> Tiger blau | J25: Bottle-Flip | M25: 9
A26: 219 | B26: 45468.456 | C26: 45468.467 | D26: anonym | F26: Blau | G26: Eule blau | I26: =OfficeForms.Table[[#This Row],[Gruppe Blau]]&OfficeForms.Table[[#This Row],[Gruppe Grün]] -> Eule blau | J26: Bottle-Flip | M26: 10
A27: 88 | B27: 45468.377 | C27: 45468.382 | D27: anonym | F27: Blau | G27: Delfin blau | I27: =OfficeForms.Table[[#This Row],[Gruppe Blau]]&OfficeForms.Table[[#This Row],[Gruppe Grün]] -> Delfin blau | J27: Bottle-Flip | M27: 11
A28: 50 | B28: 45468.36 | C28: 45468.366 | D28: anonym | F28: Blau | G28: Elefant blau | I28: =OfficeForms.Table[[#This Row],[Gruppe Blau]]&OfficeForms.Table[[#This Row],[Gruppe Grün]] -> Elefant blau | J28: Bottle-Flip | M28: 11
A29: 246 | B29: 45468.473 | C29: 45468.48 | D29: anonym | F29: Grün | H29: Igel grün | I29: =OfficeForms.Table[[#This Row],[Gruppe Blau]]&OfficeForms.Table[[#This Row],[Gruppe Grün]] -> Igel grün | J29: Bottle-Flip | M29: 12
A30: 123 | B30: 45468.398 | C30: 45468.405 | D30: anonym | F30: Grün | H30: Panda grün | I30: =OfficeForms.Table[[#This Row],[Gruppe Blau]]&OfficeForms.Table[[#This Row],[Gruppe Grün]] -> Panda grün | J30: Bottle-Flip | M30: 13
A31: 37 | B31: 45468.34 | C31: 45468.36 | D31: anonym | F31: Grün | H31: Schlange grün | I31: =OfficeForms.Table[[#This Row],[Gruppe Blau]]&OfficeForms.Table[[#This Row],[Gruppe Grün]] -> Schlange grün | J31: Bottle-Flip | M31: 13
A32: 70 | B32: 45468.366 | C32: 45468.377 | D32: anonym | F32: Grün | H32: Katze grün | I32: =OfficeForms.Table[[#This Row],[Gruppe Blau]]&OfficeForms.Table[[#This Row],[Gruppe Grün]] -> Katze grün | J32: Bottle-Flip | M32: 14
A33: 233 | B33: 45468.467 | C33: 45468.473 | D33: anonym | F33: Blau | G33: Fuchs blau | I33: =OfficeForms.Table[[#This Row],[Gruppe Blau]]&OfficeForms.Table[[#This Row],[Gruppe Grün]] -> Fuchs blau | J33: Bottle-Flip | M33: 16
A34: 281 | B34: 45468.497 | C34: 45468.497 | D34: anonym | F34: Blau | G34: Affe blau | I34: =OfficeForms.Table[[#This Row],[Gruppe Blau]]&OfficeForms.Table[[#This Row],[Gruppe Grün]] -> Affe blau | J34: Glocken-Frisbee | P34: 11
A35: 283 | B35: 45468.497 | C35: 45468.497 | D35: anonym | F35: Grün | H35: Affe grün | I35: =OfficeForms.Table[[#This Row],[Gruppe Blau]]&OfficeForms.Table[[#This Row],[Gruppe Grün]] -> Affe grün | J35: Glocken-Frisbee | P35: 11
A36: 171 | B36: 45468.439 | C36: 45468.439 | D36: anonym | F36: Blau | G36: Delfin blau | I36: =OfficeForms.Table[[#This Row],[Gruppe Blau]]&OfficeForms.Table[[#This Row],[Gruppe Grün]] -> Delfin blau | J36: Glocken-Frisbee | P36: 7
A37: 170 | B37: 45468.439 | C37: 45468.439 | D37: anonym | F37: Grün | H37: Delfin grün | I37: =OfficeForms.Table[[#This Row],[Gruppe Blau]]&OfficeForms.Table[[#This Row],[Gruppe Grün]] -> Delfin grün | J37: Glocken-Frisbee | P37: 13
A38: 161 | B38: 45468.424 | C38: 45468.424 | D38: anonym | F38: Grün | H38: Elefant grün | I38: =OfficeForms.Table[[#This Row],[Gruppe Blau]]&OfficeForms.Table[[#This Row],[Gruppe Grün]] -> Elefant grün | J38: Glocken-Frisbee | P38: 9
A39: 162 | B39: 45468.424 | C39: 45468.425 | D39: anonym | F39: Blau | G39: Elefant blau | I39: =OfficeForms.Table[[#This Row],[Gruppe Blau]]&OfficeForms.Table[[#This Row],[Gruppe Grün]] -> Elefant blau | J39: Glocken-Frisbee | P39: 16
A40: 76 | B40: 45468.38 | C40: 45468.38 | D40: anonym | F40: Grün | H40: Eule grün | I40: =OfficeForms.Table[[#This Row],[Gruppe Blau]]&OfficeForms.Table[[#This Row],[Gruppe Grün]] -> Eule grün | J40: Glocken-Frisbee | P40: 16
...

Sheet Tabelle1
B1: Gruppe
A2: Werte | B2: Affe blau | C2: Affe grün | D2: Delfin blau | E2: (Leer) | F2: Fuchs blau | G2: Delfin grün | H2: Giraffe grün | I2: Schlange blau | J2: Giraffe blau | K2: Elefant blau | L2: Fuchs grün | M2: Katze grün | N2: Eule grün | O2: Schmetterling blau | P2: Igel blau | Q2: Igel grün | S2: Schlange grün | T2: Nilpferd blau | U2: Nilpferd grün | V2: Tiger blau | W2: Schmetterling grün | X2: Schaf grün | Y2: Panda grün | Z2: Schaf blau | AA2: Panda blau | AB2: Eule blau | AC2: Elefant grün | AD2: Tiger grün | AE2: Katze blau | AF2: Krebs grün | AG2: Krebs blau | AH2: Schildkröte blau | AI2: Schildkröte grün | AJ2: Fuchs blau
A3: Summe von Paarlauf | B3: 23 | C3: 25 | D3: 9 | G3: 14 | H3: 6 | I3: 7 | J3: 10 | K3: 17 | L3: 3 | M3: 20 | N3: 1 | O3: 8 | P3: 19 | Q3: 18 | S3: 4 | T3: 18 | U3: 22 | V3: 6 | W3: 2 | X3: 21 | Y3: 24 | Z3: 15 | AA3: 19 | AB3: 16 | AC3: 16 | AD3: 21 | AE3: 13 | AF3: 5 | AG3: 12 | AH3: 8 | AI3: 11
A4: Summe von Bottle-Flip | B4: 7 | C4: 4 | D4: 10 | F4: 14 | G4: 6 | H4: 5 | I4: 7 | J4: 1 | K4: 10 | L4: 3 | M4: 13 | N4: 3 | O4: 7 | P4: 5 | Q4: 11 | S4: 12 | T4: 8 | U4: 7 | V4: 8 | W4: 8 | X4: 4 | Y4: 12 | Z4: 8 | AA4: 3 | AB4: 9 | AC4: 6 | AD4: 6 | AE4: 7 | AF4: 2 | AG4: 3 | AH4: 8 | AI4: 4
A5: Summe von Kaplaturm | B5: 2 | C5: 9 | D5: 23 | F5: 6 | G5: 21 | H5: 19 | I5: 22 | J5: 27 | K5: 13 | L5: 5 | M5: 4 | N5: 20 | O5: 12 | P5: 7 | Q5: 7 | S5: 26 | T5: 18 | U5: 20 | V5: 14 | W5: 24 | X5: 11 | Y5: 10 | Z5: 16 | AA5: 3 | AB5: 20 | AC5: 17 | AD5: 8 | AE5: 15 | AF5: 1 | AG5: 24 | AH5: 28 | AI5: 25
A6: Summe von Tic-Tac-Toe | B6: 9 | C6: 3 | D6: 4 | F6: 7 | G6: 3 | H6: 3 | I6: 5 | J6: 3 | K6: 10 | L6: 4 | M6: 10 | N6: 6 | O6: 4 | P6: 2 | Q6: 7 | S6: 6 | T6: 5 | U6: 1 | V6: 5 | W6: 6 | X6: 6 | Y6: 8 | Z6: 2 | AA6: 3 | AB6: 5 | AC6: 1 | AD6: 2 | AE6: 2 | AF6: 5 | AG6: 5 | AH6: 1 | AI6: 6
A7: Summe von Glocken-Frisbee | B7: 7 | C7: 7 | D7: 3 | G7: 9 | H7: 5 | I7: 10 | J7: 3 | K7: 12 | L7: 9 | M7: 8 | N7: 12 | O7: 2 | P7: 14 | Q7: 6 | S7: 13 | T7: 4 | U7: 6 | V7: 2 | X7: 6 | Y7: 12 | Z7: 1 | AA7: 5 | AB7: 12 | AC7: 5 | AD7: 1 | AE7: 8 | AF7: 10 | AG7: 12 | AH7: 6 | AI7: 13 | AJ7: 11
A8: Summe von Papierflieger | B8: 20 | C8: 3 | D8: 6 | F8: 21 | G8: 7 | H8: 13 | I8: 15 | J8: 4 | K8: 24 | L8: 12 | M8: 2 | N8: 27 | O8: 8 | P8: 18 | Q8: 23 | S8: 17 | T8: 7 | U8: 10 | V8: 16 | W8: 25 | X8: 15 | Y8: 14 | AA8: 1 | AB8: 11 | AC8: 22 | AD8: 5 | AE8: 28 | AF8: 26 | AG8: 9 | AH8: 19 | AI8: 10
A9: Summe von Wasser schöpfen | B9: 6 | C9: 5 | D9: 8 | F9: 3 | G9: 10 | H9: 9 | I9: 6 | J9: 1 | K9: 6 | L9: 2 | M9: 6 | N9: 2 | O9: 4 | P9: 3 | Q9: 7 | S9: 6 | T9: 4 | U9: 1 | V9: 6 | W9: 6 | X9: 6 | Y9: 6 | Z9: 5 | AA9: 3 | AB9: 6 | AC9: 5 | AD9: 7 | AE9: 10 | AF9: 3 | AG9: 7 | AH9: 9 | AI9: 6
A10: Summe von Ball Stafette | B10: 6 | C10: 7 | D10: 15 | F10: 17 | G10: 2 | H10: 19 | I10: 8 | J10: 3 | K10: 11 | L10: 4 | M10: 15 | N10: 13 | O10: 21 | P10: 8 | Q10: 9 | S10: 10 | T10: 1 | U10: 17 | V10: 4 | X10: 12 | Y10: 14 | Z10: 4 | AA10: 11 | AB10: 20 | AC10: 10 | AD10: 5 | AE10: 16 | AF10: 7 | AG10: 11 | AH10: 16 | AI10: 18
A11: Summe von Tennisball-Zielwurf | B11: 5 | C11: 4 | D11: 2 | F11: 1 | G11: 4 | H11: 1 | I11: 3 | J11: 3 | K11: 1 | L11: 3 | M11: 1 | N11: 2 | O11: 1 | P11: 2 | Q11: 2 | S11: 2 | U11: 2 | W11: 3 | X11: 1 | Z11: 6 | AA11: 3 | AB11: 2 | AC11: 3 | AE11: 4 | AF11: 4 | AG11: 2 | AH11: 2 | AI11: 3
A14: Rangpunkte: | B14: =SUM(B3:B11) -> 85 | C14: =SUM(C3:C11) -> 67 | D14: =SUM(D3:D11) -> 80 | E14: =SUM(E3:E11) -> 0 | F14: =SUM(F3:F11) -> 69 | G14: =SUM(G3:G11) -> 76 | H14: =SUM(H3:H11) -> 80 | I14: =SUM(I3:I11) -> 83 | ... AI14: =SUM(AI3:AI11) -> 96
A16: Rang: | B16: =_xlfn.RANK.EQ(B14,$B$14:$AI$14,0) -> 11 | C16: =_xlfn.RANK.EQ(C14,$B$14:$AI$14,0) -> 23 | D16: =_xlfn.RANK.EQ(D14,$B$14:$AI$14,0) -> 16 | E16: =_xlfn.RANK.EQ(E14,$B$14:$AI$14,0) -> 33 | F16: =_xlfn.RANK.EQ(F14,$B$14:$AI$14,0) -> 22 | G16: =_xlfn.RANK.EQ(G14,$B$14:$AI$14,0) -> 20 | H16: =_xlfn.RANK.EQ(H14,$B$14:$AI$14,0) -> 16 | I16: =_xlfn.RANK.EQ(I14,$B$14:$AI$14,0) -> 14 | ... AI16: =_xlfn.RANK.EQ(AI14,$B$14:$AI$14,0) -> 6

Sheet Tabelle2
A1: Rang | B1: Gruppe | C1: Punkte
A2: 1 | B2: Elefant blau | C2: =Tabelle1!K14 -> 104
A3: 2 | B3: Katze blau | C3: =Tabelle1!AE14 -> 103
A4: 3 | B4: Eule blau | C4: =Tabelle1!AB14 -> 101
A5: 4 | B5: Panda grün | C5: =Tabelle1!Y14 -> 100
A6: 5 | B6: Schildkröte blau | C6: =Tabelle1!AH14 -> 97
A7: 6 | B7: Schlange grün | C7: =Tabelle1!S14 -> 96
A8: 6 | B8: Schildkröte grün | C8: =Tabelle1!AI14 -> 96
A9: 8 | B9: Igel grün | C9: =Tabelle1!Q14 -> 90
A10: 9 | B10: Eule grün | C10: =Tabelle1!N14 -> 86
A11: 9 | B11: Nilpferd grün | C11: =Tabelle1!U14 -> 86
A12: 11 | B12: Affe blau | C12: =Tabelle1!B14 -> 85
A13: 12 | B13: Elefant grün | C13: =Tabelle1!AC14 -> 85
A14: 13 | B14: Krebs blau | C14: =Tabelle1!AG14 -> 85
A15: 14 | B15: Schlange blau | C15: =Tabelle1!I14 -> 83
A16: 15 | B16: Schaf grün | C16: =Tabelle1!X14 -> 82
A17: 16 | B17: Delfin blau | C17: =Tabelle1!D14 -> 80
A18: 17 | B18: Giraffe grün | C18: =Tabelle1!H14 -> 80
A19: 18 | B19: Katze grün | C19: =Tabelle1!M14 -> 79
A20: 19 | B20: Igel blau | C20: =Tabelle1!P14 -> 78
A21: 20 | B21: Delfin grün | C21: =Tabelle1!G14 -> 76
A22: 21 | B22: Schmetterling grün | C22: =Tabelle1!W14 -> 74
A23: 22 | B23: Fuchs blau | C23: =Tabelle1!F14 -> 69
A24: 23 | B24: Affe grün | C24: =Tabelle1!C14 -> 67
A25: 24 | B25: Schmetterling blau | C25: =Tabelle1!O14 -> 67
A26: 25 | B26: Nilpferd blau | C26: =Tabelle1!T14 -> 65
A27: 26 | B27: Krebs grün | C27: =Tabelle1!AF14 -> 63
A28: 27 | B28: Tiger blau | C28: =Tabelle1!V14 -> 61
A29: 28 | B29: Schaf blau | C29: =Tabelle1!Z14 -> 57
A30: 29 | B30: Tiger grün | C30: =Tabelle1!AD14 -> 55
A31: 30 | B31: Giraffe blau | C31: =Tabelle1!J14 -> 55
A32: 31 | B32: Panda blau | C32: =Tabelle1!AA14 -> 51
A33: 32 | B33: Fuchs grün | C33: =Tabelle1!L14 -> 45
